#VRML_SIM R2025a utf8

EXTERNPROTO "https://raw.githubusercontent.com/cyberbotics/webots/R2025a/projects/objects/backgrounds/protos/TexturedBackground.proto"
EXTERNPROTO "https://raw.githubusercontent.com/cyberbotics/webots/R2025a/projects/objects/backgrounds/protos/TexturedBackgroundLight.proto"
EXTERNPROTO "https://raw.githubusercontent.com/cyberbotics/webots/R2025a/projects/objects/floors/protos/RectangleArena.proto"

WorldInfo {
  basicTimeStep 1
  contactProperties [
    ContactProperties {
      coulombFriction -1
    }
  ]
}
Viewpoint {
  orientation -0.11774496881495629 -0.04230629094412379 0.9921422781362136 3.8264665513909306
  position 4.824100994150694 4.586109095784341 1.8473475962495833
}
TexturedBackground {
}
TexturedBackgroundLight {
}
RectangleArena {
  floorSize 100 100
  floorTileSize 5 5
}
Robot {
  translation 0 0 0.3
  children [
    Pose {
      translation 0 0.35 -0.2
      rotation 1 0 0 1.5708
      children [
        Hinge2Joint {
          jointParameters HingeJointParameters {
            axis 0 1 0
            anchor -0.575 0 0
          }
          jointParameters2 JointParameters {
            axis 0 0 -1
          }
          device [
            PositionSensor {
              name "left back steering sensor"
            }
            RotationalMotor {
              name "left back steering motor"
              maxVelocity 1000000
              maxTorque 1000000
            }
          ]
          device2 [
            PositionSensor {
              name "left back wheel sensor"
            }
            RotationalMotor {
              name "left back wheel motor"
              maxVelocity 1000000
              maxTorque 1000000
            }
          ]
          endPoint Solid {
            translation -0.575 0 0
            children [
              DEF WHEEL Shape {
                appearance PBRAppearance {
                  baseColor 0 0.666667 0
                  metalness 0
                }
                geometry Cylinder {
                  height 0.03
                  radius 0.1
                }
              }
            ]
            name "left back wheel"
            boundingObject USE WHEEL
            physics DEF WHEEL_PHYSICS Physics {
            }
          }
        }
        HingeJoint {
          jointParameters HingeJointParameters {
            axis 0 0 -1
          }
          device [
            PositionSensor {
              name "left middle wheel sensor"
            }
            RotationalMotor {
              name "left middle wheel motor"
              maxVelocity 1000000
              maxTorque 1000000
            }
          ]
          endPoint Solid {
            children [
              USE WHEEL
            ]
            name "left middle wheel"
            boundingObject USE WHEEL
            physics USE WHEEL_PHYSICS
          }
        }
        Hinge2Joint {
          jointParameters HingeJointParameters {
            anchor 0.575 0 0
            axis 0 1 0
          }
          jointParameters2 JointParameters {
            axis 0 0 -1
          }
          device [
            PositionSensor {
              name "left front steering sensor"
            }
            RotationalMotor {
              name "left front steering motor"
              maxVelocity 1000000
              maxTorque 1000000
            }
          ]
          device2 [
            PositionSensor {
              name "left front wheel sensor"
            }
            RotationalMotor {
              name "left front wheel motor"
              maxVelocity 1000000
              maxTorque 1000000
            }
          ]
          endPoint Solid {
            translation 0.575 0 0
            children [
              USE WHEEL
            ]
            name "left front wheel"
            boundingObject USE WHEEL
            physics USE WHEEL_PHYSICS
          }
        }
      ]
    }
    Pose {
      translation 0 -0.35 -0.2
      rotation 1 0 0 -1.57
      children [
        Hinge2Joint {
          jointParameters HingeJointParameters {
            anchor -0.575 0 0
            axis 0 -1 0
          }
          jointParameters2 JointParameters {
            axis 0 0 1
          }
          device [
            PositionSensor {
              name "right back steering sensor"
            }
            RotationalMotor {
              name "right back steering motor"
              maxVelocity 1000000
              maxTorque 1000000
            }
          ]
          device2 [
            PositionSensor {
              name "right back wheel sensor"
            }
            RotationalMotor {
              name "right back wheel motor"
              maxVelocity 1000000
              maxTorque 1000000
            }
          ]
          endPoint Solid {
            translation -0.575 0 0
            children [
              USE WHEEL
            ]
            name "right back wheel"
            boundingObject USE WHEEL
            physics USE WHEEL_PHYSICS
          }
        }
        HingeJoint {
          jointParameters HingeJointParameters {
            axis 0 0 1
          }
          device [
            PositionSensor {
              name "right middle wheel sensor"
            }
            RotationalMotor {
              name "right middle wheel motor"
              maxVelocity 1000000
              maxTorque 1000000
            }
          ]
          endPoint Solid {
            children [
              USE WHEEL
            ]
            name "right middle wheel"
            boundingObject USE WHEEL
            physics USE WHEEL_PHYSICS
          }
        }
        Hinge2Joint {
          jointParameters HingeJointParameters {
            axis 0 -1 0
            anchor 0.575 0 0
          }
          jointParameters2 JointParameters {
            axis 0 0 1
          }
          device [
            PositionSensor {
              name "right front steering sensor"
            }
            RotationalMotor {
              name "right front steering motor"
              maxVelocity 1000000
              maxTorque 1000000
            }
          ]
          device2 [
            PositionSensor {
              name "right front wheel sensor"
            }
            RotationalMotor {
              name "right front wheel motor"
              maxVelocity 1000000
              maxTorque 1000000
            }
          ]
          endPoint Solid {
            translation 0.575 0 0
            children [
              USE WHEEL
            ]
            name "right front wheel"
            boundingObject USE WHEEL
            physics USE WHEEL_PHYSICS
          }
        }
      ]
    }
    DEF BODY Pose {
      children [
        Shape {
          appearance Appearance {
            material Material {
            }
            name "body appearance"
          }
          geometry Box {
            size 1 0.5 0.3
          }
        }
      ]
    }
    Camera {
      translation 0.5 0 0
      recognition Recognition {
      }
    }
    GPS {
    }
    InertialUnit {
    }
  ]
  name "Rover"
  boundingObject USE BODY
  physics Physics {
  }
  controller "<extern>"
}
